<TestLog><Exception file="unknown location" line="0"><![CDATA[std::runtime_error: unexpected exception]]></Exception><Exception file="unknown location" line="0"><![CDATA[std::runtime_error: another unexpected exception]]></Exception></TestLog><TestResult><TestSuite name="MyTest" result="failed" assertions_passed="0" assertions_failed="2" expected_failures="0" test_cases_passed="0" test_cases_failed="2" test_cases_skipped="0" test_cases_aborted="2"></TestSuite></TestResult>